Workbook

Sheet Info
A1: 45729 | F1: Für Datenabfragen bitte PVCS PM Controlling AddIn installieren
A2: aktuelle KW | B2: =WEEKNUM(TODAY()) -> 53
A3: Status | B3: KW53 | F3: nach installation in Ribbon Bar zu finden unter:
A4: Projektdaten | K4: Arbeitsganggruppe | M4: Soll (h) | N4: Ist (h)
A5: Projektkategorie | B5: B | K5: Ausheizen | M5: 0 | N5: 0
A6: Projektnummer | B6: P47551 | K6: Beschriften | M6: 0.33329999 | N6: 0.34189999
A7: Kunde | B7: PFEIFFER BENELUX | K7: Dichtheitsprüfung | M7: 0 | N7: 0
A8: Projektbezeichnung | B8: horizontal vacuum chamber | K8: Drehen CNC | M8: 3.3333001 | N8: 1.9522001
A9: Umsatz | B9: 27274.5 | G9: €/$ Kurs | H9: 1.1 | K9: Drehen konventionell | M9: 4 | N9: 1.5516
A10: Nachträge | B10: A | C10: B | D10: C | E10: D | K10: Endabnahme | M10: 0 | N10: 0
C11: 0 | D11: 0 | E11: 0 | F11: =B9+B11+C11+D11+E11 -> 27274.5 | K11: Finish | M11: 12 | N11: 9.1609001
A12: VK | B12: VK2400337 | K12: Fräsen PAMA | M12: 0 | N12: 0
A13: Liefertermin AB | B13: 45915 | K13: Fräsen TOS | M13: 29.3333 | N13: 60.6031
A14: AB-Nummer | B14: AB-25-05246 | K14: Fräsen CNC | M14: 18.1666 | N14: 13.4346
A15: Projektleiter | B15: Plomer | K15: Fräsen konventionell | M15: 0 | N15: 0
A16: Konstrukteur | K16: Glasperlstrahlen | M16: 6.3333 | N16: 1.8875
K17: Montage | M17: 0 | N17: 0
K18: Montage RR | M18: 0 | N18: 0
A19: Artikelnummer(n) | B19: TR-8880-19709 | K19: QS, VT, PT | M19: 2.133 | N19: 1.119
A20: Artikelbeschreibung | B20: kundenspezfische Hochvakuumkammer DN600 Horizontal Länge: 900 mm | K20: Reinigen | M20: 15.3333 | N20: 5.3634
A21: Kommentar | K21: RGA | M21: 0 | N21: 0
K22: Schweißen Laser | M22: 4 | N22: 5.5447001
K23: Schweißen WIG | M23: 17 | N23: 15.0276
K24: Schweißen Orbital | M24: 0 | N24: 0
K25: Zuschnitt | M25: 5.4999 | N25: 5.8185
K26: sonstige | M26: 29.533 | N26: 8.8676997
K27: SUMME | M27: =SUM(M5:M26) -> 146.999 | N27: =SUM(N5:N26) -> 130.6727
D33: <-- nicht löschen oder ändern
A40: Auswertung
D41: template | E41: template | F41: KW14 | G41: KW46 | H41: KW53
A42: Vorkalkulation | B42: =+HLOOKUP($B$3,$D$41:$CT$57,2,FALSE) -> 13915.28 | C42: Vorkalkulation | D42: =+template!$J$24 -> 13915.28 | E42: =+template!$J$24 -> 13915.28 | F42: =+'KW14'!$J$24 -> 13915.28 | G42: =+'KW46'!$J$24 -> 13915.28 | H42: =+'KW53'!$J$24 -> 13915.28
A43: PM | B43: =+HLOOKUP($B$3,$D$41:$CT$57,3,FALSE) -> 1250 | C43: PM | D43: =+template!$D$24+template!$F$24 -> 1250 | E43: =+template!$D$24+template!$F$24 -> 1250 | F43: =+'KW14'!$D$24+'KW14'!$F$24 -> 1250 | G43: =+'KW46'!$D$24+'KW46'!$F$24 -> 1250 | H43: =+'KW53'!$D$24+'KW53'!$F$24 -> 1250
A44: Fertigung | B44: =+HLOOKUP($B$3,$D$41:$CT$57,4,FALSE) -> 2096.5 | C44: Fertigung | D44: =+template!$H$24 -> 2096.5 | E44: =+template!$H$24 -> 2096.5 | F44: =+'KW14'!$H$24 -> 2096.5 | G44: =+'KW46'!$H$24 -> 2096.5 | H44: =+'KW53'!$H$24 -> 2096.5
A45: Material | B45: =+HLOOKUP($B$3,$D$41:$CT$57,5,FALSE) -> 10568.78 | C45: Material | D45: =+template!$I$24 -> 10568.78 | E45: =+template!$I$24 -> 10568.78 | F45: =+'KW14'!$I$24 -> 10568.78 | G45: =+'KW46'!$I$24 -> 10568.78 | H45: =+'KW53'!$I$24 -> 10568.78
A47: Marge geplant | B47: =+HLOOKUP($B$3,$D$41:$CT$57,7,FALSE) -> 0.46429654 | C47: Marge geplant | D47: =+template!$I$4 -> 0.46429654 | E47: =+template!$I$4 -> 0.46429654 | F47: =+'KW14'!$I$4 -> 0.46429654 | G47: =+'KW46'!$I$4 -> 0.46429654 | H47: =+'KW53'!$I$4 -> 0.46429654
A48: Marge IST | B48: =+HLOOKUP($B$3,$D$41:$CT$57,8,FALSE) -> 0.81863687 | C48: Marge IST | D48: =+template!$E$233 -> 1 | E48: =+template!$E$233 -> 1 | F48: =+'KW14'!$E$233 -> 0.46103503 | G48: =+'KW46'!$E$233 -> 0.57573327 | H48: =+'KW53'!$E$233 -> 0.81863687
A50: HK Plan | B50: =+HLOOKUP($B$3,$D$41:$CT$57,10,FALSE) -> 13915.28 | C50: HK Plan | D50: =+template!$C$225 -> 13915.28 | E50: =+template!$C$225 -> 13915.28 | F50: =+'KW14'!$C$225 -> 13915.28 | G50: =+'KW46'!$C$225 -> 13915.28 | H50: =+'KW53'!$C$225 -> 13915.28
A51: HK IST | B51: =+HLOOKUP($B$3,$D$41:$CT$57,11,FALSE) -> 3070.1178 | C51: HK IST | D51: =+template!$D$225 -> 0 | E51: =+template!$D$225 -> 0 | F51: =+'KW14'!$D$225 -> 0 | G51: =+'KW46'!$D$225 -> 5136.6453 | H51: =+'KW53'!$D$225 -> 3070.1178
A53: Erwartete Gesamtkosten
A54: HK Soll | B54: =+HLOOKUP($B$3,$D$41:$CT$57,14,FALSE) -> 13915.28 | C54: HK Soll | D54: =+template!$C$230 -> 13915.28 | E54: =+template!$C$230 -> 13915.28 | F54: =+'KW14'!$C$230 -> 13915.28 | G54: =+'KW46'!$C$230 -> 13915.28 | H54: =+'KW53'!$C$230 -> 13915.28
...

Sheet Projektabschluss
A2: ="Projektabschluss "&Info!B6 -> Projektabschluss P47551
A4: =Info!B8 -> horizontal vacuum chamber
A9: Kunde | C9: =Info!B7 -> PFEIFFER BENELUX
A10: Endkunde
A11: Umsatz | C11: =Info!F11 -> 27274.5
A12: Kategorie | C12: A | D12: B | E12: C
A13: Anwendung
A14: Projektart
A17: Marge SOLL | C17: =Info!J82 -> 0.46429654
A18: Marge IST | C18: =Info!K82 -> 0.81863687
A19: Marge IST | C19: =Info!K83 -> 22563.463
A20: Lieferung
A22: Kurzbeschreibung Produkt
A26: Kommentare zu Projektergebnis und Lieferzeit
A34: Platz für Bilder
A46: Lessons Learned
A47: Thema | H47: Maßnahme | O47: Fachbereich

Sheet Arbeitsgänge
A1: Arbeitsgang | B1: Bezeichnung | C1: IST (h) | D1: Soll (h)
A2: AG000007 | B2: Beschriften (Laserbeschriften) - Typenschild beschriftet | C2: 0.3419 | D2: 0.3333
A3: AG000059 | B3: Drehen - CNC - Vordrehen mit Gewinde | C3: 1.9522 | D3: 3.3333
A4: AG000031 | B4: Drehen - Konventionell - Rohre plandrehen, Flansche anpassen | C4: 1.5516 | D4: 4
A5: AG000014 | B5: Finish - Dichtflächen herstellen und vorbereiten zum Elektropolieren | C5: 3.3852 | D5: 2
A6: AG000014 | B6: Finish - Dichtflächen herstellen und vorbereiten zum Elektropolieren | C6: 3.3055 | D6: 2
A7: AG000014 | B7: Finish - Kammerkorpus, DN 600 | C7: 2.4702 | D7: 4
A8: AG000014 | B8: Finish - Kammerkorpus, DN 600 | C8: 0 | D8: 2
A9: AG000014 | B9: Finish - Tür DN600 bearbeitet | C9: 0 | D9: 1
A10: AG000014 | B10: Finish - Tür DN600 bearbeitet | C10: 0 | D10: 1
A11: AG000035 | B11: Fräsen - Bohrwerk TOS - Füße und Kammerflansche fertig fräsen | C11: 23.5027 | D11: 10
A12: AG000035 | B12: Fräsen - Bohrwerk TOS - Grundrohr planfräsen, Flansche anpassen | C12: 8.4377 | D12: 5.3333
A13: AG000035 | B13: Fräsen - Bohrwerk TOS - Kammer bohren | C13: 3.0833 | D13: 6
... A65: AG000011 | B65: Zuschnitt - Stabstahl beistellen | C65: 0.3869 | D65: 0.3333

Sheet BSP
B3: Auftraggeber | C3: Projektleiter | D3: Projektnummer | E3: Projektkategorie | F3: Umsatz | G3: Liefertermin AB | H3: Endtermin | I3: Marge geplant | J3: Gesamtstatus
B4: =+Info!B7 -> PFEIFFER BENELUX | C4: =+Info!B15 -> Plomer | D4: =+Info!B6 -> P47551 | E4: =+Info!B5 -> B | F4: =+Info!B9+Info!B11+Info!C11+Info!D11+Info!E11 -> 27274.5 | G4: =+Info!#REF! -> #REF! | H4: =+Info!#REF! -> #REF! | I4: =(F4-(J24*1.04))/F4 -> 0.99824598
B6: Projektteam | C6: =+Info!B18 -> 0
B7: Artikelnummer(n) | C7: =+Info!B19 -> TR-8880-19709
B8: Artikelbeschreibung | C8: =+Info!B20 -> kundenspezfische Hochvakuumkammer DN600 Horizontal Länge: 900 mm
B9: Besonderheiten | C9: =+Info!B21 -> 0
B11: Vorkalkulation(en) | L11: Kommentar: -
C12: PM (PMK) | E12: Konstruktion (KOK) | G12: Fertigung | I12: Material | J12: Gesamt
C13: Stunden | D13: Kosten | E13: Stunden | F13: Kosten | G13: Stunden | H13: Kosten | I13: Kosten
C14: 0 | D14: =+C14*46 -> 0 | E14: 1 | F14: =E14*46 -> 46 | G14: 0 | H14: 0 | I14: 0 | J14: =+D14+F14+H14+I14 -> 46
C15: 0 | D15: =+C15*46 -> 0 | E15: 0 | F15: =E15*46 -> 0 | G15: 0 | H15: 0 | I15: 0 | J15: =+D15+F15+H15+I15 -> 0
C16: 0 | D16: =+C16*46 -> 0 | E16: 0 | F16: =E16*46 -> 0 | G16: 0 | H16: 0 | I16: 0 | J16: =+D16+F16+H16+I16 -> 0
C17: 0 | D17: =+C17*46 -> 0 | E17: 0 | F17: =E17*46 -> 0 | G17: 0 | H17: 0 | I17: 0 | J17: =+D17+F17+H17+I17 -> 0
C18: 0 | D18: =+C18*46 -> 0 | E18: 0 | F18: =E18*46 -> 0 | G18: 0 | H18: 0 | I18: 0 | J18: =+D18+F18+H18+I18 -> 0
C19: 0 | D19: =+C19*46 -> 0 | E19: 0 | F19: =E19*46 -> 0 | G19: 0 | H19: 0 | I19: 0 | J19: =+D19+F19+H19+I19 -> 0
C20: 0 | D20: =+C20*46 -> 0 | E20: 0 | F20: =E20*46 -> 0 | G20: 0 | H20: 0 | I20: 0 | J20: =+D20+F20+H20+I20 -> 0
C21: 0 | D21: =+C21*46 -> 0 | E21: 0 | F21: =E21*46 -> 0 | G21: 0 | H21: 0 | I21: 0 | J21: =+D21+F21+H21+I21 -> 0
C22: 0 | D22: =+C22*46 -> 0 | E22: 0 | F22: =E22*46 -> 0 | G22: 0 | H22: 0 | I22: 0 | J22: =+D22+F22+H22+I22 -> 0
C23: 0 | D23: =+C23*46 -> 0 | E23: 0 | F23: =E23*46 -> 0 | G23: 0 | H23: 0 | I23: 0 | J23: =+D23+F23+H23+I23 -> 0
B24: Gesamt | C24: =SUM(C14:C23) -> 0 | D24: =SUM(D14:D23) -> 0 | E24: =SUM(E14:E23) -> 1 | F24: =SUM(F14:F23) -> 46 | G24: =SUM(G14:G23) -> 0 | H24: =SUM(H14:H23) -> 0 | I24: =SUM(I14:I23) -> 0 | J24: =(D24+F24+H24+I24) -> 46
B26: PM | C26: PMK | D26: Konstruktion | E26: KOK | L26: Kommentar: - Bisher in MF erfaßt Stunden
B27: Stunden | C27: Kosten | D27: Stunden | E27: Kosten
C28: =B28*46 -> 0 | D28: 1 | E28: =D28*46 -> 46
B30: Einkauf | L30: Kommentar: - Beschreibung = Lieferant oder Ware (z.B. "Werinox","Plattenmaterial", "Kammerrahmen", etc) - Kommentar = z.B. "angefragt", "bestellt", "geliefert" - Wert = Bestellwert MF - in PA = Nach PA-Beginn wird "Wert" nach rechts "in PA" verschoben und "Wert" auf null gesetzt. Dies kann anteilig nötig sein wenn bestelltes Material in verschiede PAs aufgeht.
B31: Beschreibung | C31: BE-Nummer | D31: Kommentar | F31: Wert | G31: in PA
F32: 0
B47: Gesamt | F47: =SUM(F32:F46) -> 0 | G47: EKM
B49: Produktion | C49: laufende PAs | G49: Plankosten | H49: abgeschlossene PAs | L49: PA Auswertung Status und Lohnkosten | P49: Kommentar: - Reihenfolge der PA-Einträge muss Reihenfolge in MF entsprechen - Plankosten = Summe der Lohn-Plankosten MF - Arbeit = Summe der Lohn-Istkosten MF - offene Arbeit = Plankosten minus Lohn-Plankosten (MF) der abgeschlossenen Arbeitsschritte - Abgeschlossene PAs, die noch nciht aufgegangen sind, werden ausgegraut - Abgeschlossenen PAs, die aufgegangen sind, werden anch rechts verschoben und links entfernt
B50: Produktionsaufträge | C50: Arbeit | D50: Material | E50: Summe | F50: offen Arbeit | G50: Arbeit | H50: Arbeit | I50: Material | J50: Summe | K50: PA-Name | L50: Erwartete Abarbeitung | M50: Verbrauchte Plankosten | N50: Kostenabweichung
B51: PA1 | D51: 4708 | E51: =SUM(C51:D51) -> 4708 | F51: =G51 -> 1050 | G51: 1050 | H51: 0 | I51: 0 | J51: =SUM(H51:I51) -> 0 | K51: Kammer montiert | L51: =IF(AND(G51>0,OR(C51>0,F51>0,H51>0)),(G51-F51)/G51,"") -> 0 | M51: =IF(G51>0,(IF(C51>0,C51,H51))/G51,"") -> 0 | N51: =IF(L51=100%,G51-(IF(C51>0,C51,H51)),"")
B52: PA2 | E52: =SUM(C52:D52) -> 0 | F52: =G52-745 -> 0 | G52: 745 | H52: 809 | I52: 0 | J52: =SUM(H52:I52) -> 809 | K52: Tür | L52: =IF(AND(G52>0,OR(C52>0,F52>0,H52>0)),(G52-F52)/G52,"") -> 1 | M52: =IF(G52>0,(IF(C52>0,C52,H52))/G52,"") -> 1.085906 | N52: =IF(L52=100%,G52-(IF(C52>0,C52,H52)),"") -> -64
B53: PA3 | C53: 200 | E53: 0 | F53: =G53-160 -> 150 | G53: 310 | H53: 0 | I53: 0 | J53: =SUM(H53:I53) -> 0 | K53: Aufsatz | L53: =IF(AND(G53>0,OR(C53>0,F53>0,H53>0)),(G53-F53)/G53,"") -> 0.51612903 | M53: =IF(G53>0,(IF(C53>0,C53,H53))/G53,"") -> 0.64516129 | N53: =IF(L53=100%,G53-(IF(C53>0,C53,H53)),"")
B54: PA4 | E54: 0 | F54: =G54-G54 -> 0 | G54: 4004 | H54: 3899 | I54: 0 | J54: =SUM(H54:I54) -> 3899 | K54: Kammer roh | L54: =IF(AND(G54>0,OR(C54>0,F54>0,H54>0)),(G54-F54)/G54,"") -> 1 | M54: =IF(G54>0,(IF(C54>0,C54,H54))/G54,"") -> 0.97377622 | N54: =IF(L54=100%,G54-(IF(C54>0,C54,H54)),"") -> 105
B55: PA5 | E55: =SUM(C55:D55) -> 0 | F55: =G55 -> 23 | G55: 23 | H55: 0 | I55: 0 | J55: =SUM(H55:I55) -> 0 | K55: Typenschild | L55: =IF(AND(G55>0,OR(C55>0,F55>0,H55>0)),(G55-F55)/G55,"") -> 0 | M55: =IF(G55>0,(IF(C55>0,C55,H55))/G55,"") -> 0 | N55: =IF(L55=100%,G55-(IF(C55>0,C55,H55)),"")
B56: PA6 | C56: 8 | E56: =SUM(C56:D56) -> 8 | F56: =G56-10 -> 1.5 | G56: 11.5 | H56: 0 | I56: 0 | J56: =SUM(H56:I56) -> 0 | K56: Bolzen | L56: =IF(AND(G56>0,OR(C56>0,F56>0,H56>0)),(G56-F56)/G56,"") -> 0.86956522 | M56: =IF(G56>0,(IF(C56>0,C56,H56))/G56,"") -> 0.69565217 | N56: =IF(L56=100%,G56-(IF(C56>0,C56,H56)),"")
B57: PA7 | C57: 2000 | D57: 1000 | E57: =SUM(C57:D57) -> 3000 | F57: =G57-687 -> 322.34 | G57: 1009.34 | H57: 0 | I57: 0 | J57: =SUM(H57:I57) -> 0 | K57: Cooling plate | L57: =IF(AND(G57>0,OR(C57>0,F57>0,H57>0)),(G57-F57)/G57,"") -> 0.6806428 | M57: =IF(G57>0,(IF(C57>0,C57,H57))/G57,"") -> 1.9814929 | N57: =IF(L57=100%,G57-(IF(C57>0,C57,H57)),"")
B58: PA8 | E58: =SUM(C58:D58) -> 0 | F58: =G58+24 -> 101.03 | G58: 77.03 | H58: 0 | I58: 0 | J58: =SUM(H58:I58) -> 0 | K58: Einschub | L58: =IF(AND(G58>0,OR(C58>0,F58>0,H58>0)),(G58-F58)/G58,"") -> -0.31156692 | M58: =IF(G58>0,(IF(C58>0,C58,H58))/G58,"") -> 0 | N58: =IF(L58=100%,G58-(IF(C58>0,C58,H58)),"")
B59: PA9 | C59: 15.9 | E59: =SUM(C59:D59) -> 15.9 | F59: =G59-18 -> 6.12 | G59: 24.12 | H59: 0 | I59: 0 | J59: =SUM(H59:I59) -> 0 | K59: Halter links | L59: =IF(AND(G59>0,OR(C59>0,F59>0,H59>0)),(G59-F59)/G59,"") -> 0.74626866 | M59: =IF(G59>0,(IF(C59>0,C59,H59))/G59,"") -> 0.65920398 | N59: =IF(L59=100%,G59-(IF(C59>0,C59,H59)),"")
B60: PA10 | C60: 12 | E60: =SUM(C60:D60) -> 12 | F60: 0 | G60: 24.12 | H60: 0 | I60: 0 | J60: =SUM(H60:I60) -> 0 | K60: Halter rechts | L60: =IF(AND(G60>0,OR(C60>0,F60>0,H60>0)),(G60-F60)/G60,"") -> 1 | M60: =IF(G60>0,(IF(C60>0,C60,H60))/G60,"") -> 0.49751244 | N60: =IF(L60=100%,G60-(IF(C60>0,C60,H60)),"") -> 12.12
E61: =SUM(C61:D61) -> 0 | H61: 0 | I61: 0 | J61: =SUM(H61:I61) -> 0 | L61: =IF(AND(G61>0,OR(C61>0,F61>0,H61>0)),(G61-F61)/G61,"") | M61: =IF(G61>0,(IF(C61>0,C61,H61))/G61,"") | N61: =IF(L61=100%,G61-(IF(C61>0,C61,H61)),"")
...

Sheet template
M2: Kommentar: - Stundensatz Jan 2024 auf 50€ erhöht - Bitte in VK eintragen wie in VK gerechnet
B3: Auftraggeber | C3: Projektleiter | D3: Projektnummer | E3: Projektkategorie | F3: Umsatz | G3: Liefertermin AB | H3: Endtermin | I3: Marge geplant | J3: Gesamtstatus
B4: =+Info!B7 -> PFEIFFER BENELUX | C4: =+Info!B15 -> Plomer | D4: =+Info!B6 -> P47551 | E4: =+Info!B5 -> B | F4: =+Info!B9+Info!B11+Info!C11+Info!D11+Info!E11 -> 27274.5 | G4: =+Info!B13 -> 45915 | I4: =(F4-(J24*1.05))/F4 -> 0.46429654
B7: Artikelnummer(n) | C7: =+Info!B19 -> TR-8880-19709
B8: Artikelbeschreibung | C8: =+Info!B20 -> kundenspezfische Hochvakuumkammer DN600 Horizontal Länge: 900 mm
B9: Besonderheiten | C9: =+Info!B21 -> 0
B11: Vorkalkulation(en)
C12: PM (PMK) | E12: Konstruktion (KOK) | G12: Fertigung | I12: Material | J12: Gesamt
C13: Stunden | D13: Kosten | E13: Stunden | F13: Kosten | G13: Stunden | H13: Kosten | I13: Kosten
B14: VK2400337 | C14: 5 | D14: 250 | E14: 20 | F14: 1000 | H14: 2096.5 | I14: 10568.78 | J14: 13915.28
D15: =C15*53 -> 0 | F15: =E15*53 -> 0 | J15: =+D15+F15+H15+I15 -> 0
D16: =C16*53 -> 0 | F16: =E16*53 -> 0 | J16: =+D16+F16+H16+I16 -> 0
D17: =C17*53 -> 0 | F17: =E17*53 -> 0 | J17: =+D17+F17+H17+I17 -> 0 | M17: Kommentar: - Bisher in MF erfaßt Stunden
D18: =C18*53 -> 0 | F18: =E18*53 -> 0 | J18: =+D18+F18+H18+I18 -> 0
D19: =C19*53 -> 0 | F19: =E19*53 -> 0 | J19: =+D19+F19+H19+I19 -> 0
D20: =C20*53 -> 0 | F20: =E20*53 -> 0 | J20: =+D20+F20+H20+I20 -> 0
D21: =C21*53 -> 0 | F21: =E21*53 -> 0 | J21: =+D21+F21+H21+I21 -> 0 | M21: Kommentar: - Beschreibung = Lieferant oder Ware (z.B. "Werinox","Plattenmaterial", "Kammerrahmen", etc) - Kommentar = z.B. "angefragt", "bestellt", "geliefert" - Wert = Bestellwert MF - in PA = Nach PA-Beginn wird "Wert" nach rechts "in PA" verschoben und "Wert" auf null gesetzt. Dies kann anteilig nötig sein wenn bestelltes Material in verschiede PAs aufgeht.
D22: =C22*53 -> 0 | F22: =E22*53 -> 0 | J22: =+D22+F22+H22+I22 -> 0
D23: =C23*53 -> 0 | F23: =E23*53 -> 0 | J23: =+D23+F23+H23+I23 -> 0
B24: Gesamt | C24: =SUM(C14:C23) -> 5 | D24: =SUM(D14:D23) -> 250 | E24: =SUM(E14:E23) -> 20 | F24: =SUM(F14:F23) -> 1000 | G24: =SUM(G14:G23) -> 0 | H24: =SUM(H14:H23) -> 2096.5 | I24: =SUM(I14:I23) -> 10568.78 | J24: =SUM(J14:J23) -> 13915.28
B26: PM | C26: PMK | D26: Konstruktion | E26: KOK | F26: VK / Vertriebsunterstützung
B28: Stunden | C28: Kosten | D28: Stunden | E28: Kosten | F28: Stunden | G28: Kosten
C29: =B29*53 -> 0 | E29: =D29*53 -> 0 | G29: =F29*53 -> 0
B31: Einkauf
B32: Beschreibung | C32: BE-Nummer | D32: Kommentar | F32: Wert | G32: in PA
B48: Gesamt | F48: =SUM(F33:F47) -> 0 | G48: EKM
B50: Produktion | C50: laufende PAs | G50: Lohn-Plankosten | H50: abgeschlossene PAs | M50: PA Auswertung Status und Lohnkosten | Q50: Kommentar: - Reihenfolge der PA-Einträge muss Reihenfolge in MF entsprechen - Plankosten = Summe der Lohn-Plankosten MF - Arbeit = Summe der Lohn-Istkosten MF - offene Arbeit = Plankosten minus Lohn-Plankosten (MF) der abgeschlossenen Arbeitsschritte - Abgeschlossene PAs, die noch nciht aufgegangen sind, werden ausgegraut - Abgeschlossenen PAs, die aufgegangen sind, werden anch rechts verschoben und links entfernt
B51: Produktionsaufträge | C51: Arbeit | D51: Material | E51: Summe | F51: offen Arbeit | G51: Arbeit | H51: Arbeit | I51: Material | J51: Summe | K51: Status | L51: Artikel Nr. - Bezeichnung | M51: Erwartete Abarbeitung | N51: Verbrauchte Plankosten | O51: Kostenabweichung
E52: =C52+D52 -> 0 | J52: =H52+I52 -> 0 | M52: =IF(AND(G52>0,OR(C52>0,F52>0,H52>0)),(G52-F52)/G52,"") | N52: =IF(G52>0,(IF(C52>0,C52,H52))/G52,"") | O52: =IF(M52=100%,G52-(IF(C52>0,C52,H52)),"") | P52: 40866
E53: =C53+D53 -> 0 | J53: =H53+I53 -> 0 | M53: =IF(AND(G53>0,OR(C53>0,F53>0,H53>0)),(G53-F53)/G53,"") | N53: =IF(G53>0,(IF(C53>0,C53,H53))/G53,"") | O53: =IF(M53=100%,G53-(IF(C53>0,C53,H53)),"") | P53: 40867
E54: =C54+D54 -> 0 | J54: =H54+I54 -> 0 | M54: =IF(AND(G54>0,OR(C54>0,F54>0,H54>0)),(G54-F54)/G54,"") | N54: =IF(G54>0,(IF(C54>0,C54,H54))/G54,"") | O54: =IF(M54=100%,G54-(IF(C54>0,C54,H54)),"") | P54: 40868
E55: =C55+D55 -> 0 | J55: =H55+I55 -> 0 | M55: =IF(AND(G55>0,OR(C55>0,F55>0,H55>0)),(G55-F55)/G55,"") | N55: =IF(G55>0,(IF(C55>0,C55,H55))/G55,"") | O55: =IF(M55=100%,G55-(IF(C55>0,C55,H55)),"") | P55: 40869
E56: =C56+D56 -> 0 | J56: =H56+I56 -> 0 | M56: =IF(AND(G56>0,OR(C56>0,F56>0,H56>0)),(G56-F56)/G56,"") | N56: =IF(G56>0,(IF(C56>0,C56,H56))/G56,"") | O56: =IF(M56=100%,G56-(IF(C56>0,C56,H56)),"") | P56: 40870
E57: =C57+D57 -> 0 | J57: =H57+I57 -> 0 | M57: =IF(AND(G57>0,OR(C57>0,F57>0,H57>0)),(G57-F57)/G57,"") | N57: =IF(G57>0,(IF(C57>0,C57,H57))/G57,"") | O57: =IF(M57=100%,G57-(IF(C57>0,C57,H57)),"") | P57: 40871
E58: =C58+D58 -> 0 | J58: =H58+I58 -> 0 | M58: =IF(AND(G58>0,OR(C58>0,F58>0,H58>0)),(G58-F58)/G58,"") | N58: =IF(G58>0,(IF(C58>0,C58,H58))/G58,"") | O58: =IF(M58=100%,G58-(IF(C58>0,C58,H58)),"") | P58: 40872
E59: =C59+D59 -> 0 | J59: =H59+I59 -> 0 | M59: =IF(AND(G59>0,OR(C59>0,F59>0,H59>0)),(G59-F59)/G59,"") | N59: =IF(G59>0,(IF(C59>0,C59,H59))/G59,"") | O59: =IF(M59=100%,G59-(IF(C59>0,C59,H59)),"") | P59: 40882
E60: =C60+D60 -> 0 | J60: =H60+I60 -> 0 | M60: =IF(AND(G60>0,OR(C60>0,F60>0,H60>0)),(G60-F60)/G60,"") | N60: =IF(G60>0,(IF(C60>0,C60,H60))/G60,"") | O60: =IF(M60=100%,G60-(IF(C60>0,C60,H60)),"") | P60: 41044
E61: =C61+D61 -> 0 | J61: =H61+I61 -> 0 | M61: =IF(AND(G61>0,OR(C61>0,F61>0,H61>0)),(G61-F61)/G61,"") | N61: =IF(G61>0,(IF(C61>0,C61,H61))/G61,"") | O61: =IF(M61=100%,G61-(IF(C61>0,C61,H61)),"")
E62: =C62+D62 -> 0 | J62: =H62+I62 -> 0 | M62: =IF(AND(G62>0,OR(C62>0,F62>0,H62>0)),(G62-F62)/G62,"") | N62: =IF(G62>0,(IF(C62>0,C62,H62))/G62,"") | O62: =IF(M62=100%,G62-(IF(C62>0,C62,H62)),"")
E63: =C63+D63 -> 0 | J63: =H63+I63 -> 0 | M63: =IF(AND(G63>0,OR(C63>0,F63>0,H63>0)),(G63-F63)/G63,"") | N63: =IF(G63>0,(IF(C63>0,C63,H63))/G63,"") | O63: =IF(M63=100%,G63-(IF(C63>0,C63,H63)),"")
...

Sheet KW14
M2: Kommentar: - Stundensatz Jan 2024 auf 50€ erhöht - Bitte in VK eintragen wie in VK gerechnet
B3: Auftraggeber | C3: Projektleiter | D3: Projektnummer | E3: Projektkategorie | F3: Umsatz | G3: Liefertermin AB | H3: Endtermin | I3: Marge geplant | J3: Gesamtstatus
B4: =+Info!B7 -> PFEIFFER BENELUX | C4: =+Info!B15 -> Plomer | D4: =+Info!B6 -> P47551 | E4: =+Info!B5 -> B | F4: =+Info!B9+Info!B11+Info!C11+Info!D11+Info!E11 -> 27274.5 | G4: =+Info!B13 -> 45915 | I4: =(F4-(J24*1.05))/F4 -> 0.46429654
B7: Artikelnummer(n) | C7: =+Info!B19 -> TR-8880-19709
B8: Artikelbeschreibung | C8: =+Info!B20 -> kundenspezfische Hochvakuumkammer DN600 Horizontal Länge: 900 mm
B9: Besonderheiten | C9: =+Info!B21 -> 0
B11: Vorkalkulation(en)
C12: PM (PMK) | E12: Konstruktion (KOK) | G12: Fertigung | I12: Material | J12: Gesamt
C13: Stunden | D13: Kosten | E13: Stunden | F13: Kosten | G13: Stunden | H13: Kosten | I13: Kosten
B14: VK2400337 | C14: 5 | D14: 250 | E14: 20 | F14: 1000 | H14: 2096.5 | I14: 10568.78 | J14: 13915.28
D15: =C15*53 -> 0 | F15: =E15*53 -> 0 | J15: =+D15+F15+H15+I15 -> 0
D16: =C16*53 -> 0 | F16: =E16*53 -> 0 | J16: =+D16+F16+H16+I16 -> 0
D17: =C17*53 -> 0 | F17: =E17*53 -> 0 | J17: =+D17+F17+H17+I17 -> 0 | M17: Kommentar: - Bisher in MF erfaßt Stunden
D18: =C18*53 -> 0 | F18: =E18*53 -> 0 | J18: =+D18+F18+H18+I18 -> 0
D19: =C19*53 -> 0 | F19: =E19*53 -> 0 | J19: =+D19+F19+H19+I19 -> 0
D20: =C20*53 -> 0 | F20: =E20*53 -> 0 | J20: =+D20+F20+H20+I20 -> 0
D21: =C21*53 -> 0 | F21: =E21*53 -> 0 | J21: =+D21+F21+H21+I21 -> 0 | M21: Kommentar: - Beschreibung = Lieferant oder Ware (z.B. "Werinox","Plattenmaterial", "Kammerrahmen", etc) - Kommentar = z.B. "angefragt", "bestellt", "geliefert" - Wert = Bestellwert MF - in PA = Nach PA-Beginn wird "Wert" nach rechts "in PA" verschoben und "Wert" auf null gesetzt. Dies kann anteilig nötig sein wenn bestelltes Material in verschiede PAs aufgeht.
D22: =C22*53 -> 0 | F22: =E22*53 -> 0 | J22: =+D22+F22+H22+I22 -> 0
D23: =C23*53 -> 0 | F23: =E23*53 -> 0 | J23: =+D23+F23+H23+I23 -> 0
B24: Gesamt | C24: =SUM(C14:C23) -> 5 | D24: =SUM(D14:D23) -> 250 | E24: =SUM(E14:E23) -> 20 | F24: =SUM(F14:F23) -> 1000 | G24: =SUM(G14:G23) -> 0 | H24: =SUM(H14:H23) -> 2096.5 | I24: =SUM(I14:I23) -> 10568.78 | J24: =SUM(J14:J23) -> 13915.28
B26: PM | C26: PMK | D26: Konstruktion | E26: KOK | F26: VK / Vertriebsunterstützung
B28: Stunden | C28: Kosten | D28: Stunden | E28: Kosten | F28: Stunden | G28: Kosten
C29: =B29*53 -> 0 | E29: =D29*53 -> 0 | G29: =F29*53 -> 0
B31: Einkauf
B32: Beschreibung | C32: BE-Nummer | D32: Kommentar | F32: Wert | G32: in PA
B48: Gesamt | F48: =SUM(F33:F47) -> 0 | G48: EKM
B50: Produktion | C50: laufende PAs | G50: Lohn-Plankosten | H50: abgeschlossene PAs | M50: PA Auswertung Status und Lohnkosten | Q50: Kommentar: - Reihenfolge der PA-Einträge muss Reihenfolge in MF entsprechen - Plankosten = Summe der Lohn-Plankosten MF - Arbeit = Summe der Lohn-Istkosten MF - offene Arbeit = Plankosten minus Lohn-Plankosten (MF) der abgeschlossenen Arbeitsschritte - Abgeschlossene PAs, die noch nciht aufgegangen sind, werden ausgegraut - Abgeschlossenen PAs, die aufgegangen sind, werden anch rechts verschoben und links entfernt
B51: Produktionsaufträge | C51: Arbeit | D51: Material | E51: Summe | F51: offen Arbeit | G51: Arbeit | H51: Arbeit | I51: Material | J51: Summe | K51: Status | L51: Artikel Nr. - Bezeichnung | M51: Erwartete Abarbeitung | N51: Verbrauchte Plankosten | O51: Kostenabweichung
E52: =C52+D52 -> 0 | J52: =H52+I52 -> 0 | M52: =IF(AND(G52>0,OR(C52>0,F52>0,H52>0)),(G52-F52)/G52,"") | N52: =IF(G52>0,(IF(C52>0,C52,H52))/G52,"") | O52: =IF(M52=100%,G52-(IF(C52>0,C52,H52)),"") | P52: 40866
E53: =C53+D53 -> 0 | J53: =H53+I53 -> 0 | M53: =IF(AND(G53>0,OR(C53>0,F53>0,H53>0)),(G53-F53)/G53,"") | N53: =IF(G53>0,(IF(C53>0,C53,H53))/G53,"") | O53: =IF(M53=100%,G53-(IF(C53>0,C53,H53)),"") | P53: 40867
E54: =C54+D54 -> 0 | J54: =H54+I54 -> 0 | M54: =IF(AND(G54>0,OR(C54>0,F54>0,H54>0)),(G54-F54)/G54,"") | N54: =IF(G54>0,(IF(C54>0,C54,H54))/G54,"") | O54: =IF(M54=100%,G54-(IF(C54>0,C54,H54)),"") | P54: 40868
E55: =C55+D55 -> 0 | J55: =H55+I55 -> 0 | M55: =IF(AND(G55>0,OR(C55>0,F55>0,H55>0)),(G55-F55)/G55,"") | N55: =IF(G55>0,(IF(C55>0,C55,H55))/G55,"") | O55: =IF(M55=100%,G55-(IF(C55>0,C55,H55)),"") | P55: 40869
E56: =C56+D56 -> 0 | J56: =H56+I56 -> 0 | M56: =IF(AND(G56>0,OR(C56>0,F56>0,H56>0)),(G56-F56)/G56,"") | N56: =IF(G56>0,(IF(C56>0,C56,H56))/G56,"") | O56: =IF(M56=100%,G56-(IF(C56>0,C56,H56)),"") | P56: 40870
E57: =C57+D57 -> 0 | J57: =H57+I57 -> 0 | M57: =IF(AND(G57>0,OR(C57>0,F57>0,H57>0)),(G57-F57)/G57,"") | N57: =IF(G57>0,(IF(C57>0,C57,H57))/G57,"") | O57: =IF(M57=100%,G57-(IF(C57>0,C57,H57)),"") | P57: 40871
E58: =C58+D58 -> 0 | J58: =H58+I58 -> 0 | M58: =IF(AND(G58>0,OR(C58>0,F58>0,H58>0)),(G58-F58)/G58,"") | N58: =IF(G58>0,(IF(C58>0,C58,H58))/G58,"") | O58: =IF(M58=100%,G58-(IF(C58>0,C58,H58)),"") | P58: 40872
E59: =C59+D59 -> 0 | J59: =H59+I59 -> 0 | M59: =IF(AND(G59>0,OR(C59>0,F59>0,H59>0)),(G59-F59)/G59,"") | N59: =IF(G59>0,(IF(C59>0,C59,H59))/G59,"") | O59: =IF(M59=100%,G59-(IF(C59>0,C59,H59)),"") | P59: 40882
E60: =C60+D60 -> 0 | J60: =H60+I60 -> 0 | M60: =IF(AND(G60>0,OR(C60>0,F60>0,H60>0)),(G60-F60)/G60,"") | N60: =IF(G60>0,(IF(C60>0,C60,H60))/G60,"") | O60: =IF(M60=100%,G60-(IF(C60>0,C60,H60)),"") | P60: 41044
E61: =C61+D61 -> 0 | J61: =H61+I61 -> 0 | M61: =IF(AND(G61>0,OR(C61>0,F61>0,H61>0)),(G61-F61)/G61,"") | N61: =IF(G61>0,(IF(C61>0,C61,H61))/G61,"") | O61: =IF(M61=100%,G61-(IF(C61>0,C61,H61)),"")
E62: =C62+D62 -> 0 | J62: =H62+I62 -> 0 | M62: =IF(AND(G62>0,OR(C62>0,F62>0,H62>0)),(G62-F62)/G62,"") | N62: =IF(G62>0,(IF(C62>0,C62,H62))/G62,"") | O62: =IF(M62=100%,G62-(IF(C62>0,C62,H62)),"")
E63: =C63+D63 -> 0 | J63: =H63+I63 -> 0 | M63: =IF(AND(G63>0,OR(C63>0,F63>0,H63>0)),(G63-F63)/G63,"") | N63: =IF(G63>0,(IF(C63>0,C63,H63))/G63,"") | O63: =IF(M63=100%,G63-(IF(C63>0,C63,H63)),"")
...

Sheet KW46
M2: Kommentar: - Stundensatz Jan 2024 auf 50€ erhöht - Bitte in VK eintragen wie in VK gerechnet
B3: Auftraggeber | C3: Projektleiter | D3: Projektnummer | E3: Projektkategorie | F3: Umsatz | G3: Liefertermin AB | H3: Endtermin | I3: Marge geplant | J3: Gesamtstatus
B4: =+Info!B7 -> PFEIFFER BENELUX | C4: =+Info!B15 -> Plomer | D4: =+Info!B6 -> P47551 | E4: =+Info!B5 -> B | F4: =+Info!B9+Info!B11+Info!C11+Info!D11+Info!E11 -> 27274.5 | G4: =+Info!B13 -> 45915 | I4: =(F4-(J24*1.05))/F4 -> 0.46429654
B7: Artikelnummer(n) | C7: =+Info!B19 -> TR-8880-19709
B8: Artikelbeschreibung | C8: =+Info!B20 -> kundenspezfische Hochvakuumkammer DN600 Horizontal Länge: 900 mm
B9: Besonderheiten | C9: =+Info!B21 -> 0
B11: Vorkalkulation(en)
C12: PM (PMK) | E12: Konstruktion (KOK) | G12: Fertigung | I12: Material | J12: Gesamt
C13: Stunden | D13: Kosten | E13: Stunden | F13: Kosten | G13: Stunden | H13: Kosten | I13: Kosten
B14: VK2400337 | C14: 5 | D14: 250 | E14: 20 | F14: 1000 | H14: 2096.5 | I14: 10568.78 | J14: 13915.28
D15: =C15*53 -> 0 | F15: =E15*53 -> 0 | J15: =+D15+F15+H15+I15 -> 0
D16: =C16*53 -> 0 | F16: =E16*53 -> 0 | J16: =+D16+F16+H16+I16 -> 0
D17: =C17*53 -> 0 | F17: =E17*53 -> 0 | J17: =+D17+F17+H17+I17 -> 0 | M17: Kommentar: - Bisher in MF erfaßt Stunden
D18: =C18*53 -> 0 | F18: =E18*53 -> 0 | J18: =+D18+F18+H18+I18 -> 0
D19: =C19*53 -> 0 | F19: =E19*53 -> 0 | J19: =+D19+F19+H19+I19 -> 0
D20: =C20*53 -> 0 | F20: =E20*53 -> 0 | J20: =+D20+F20+H20+I20 -> 0
D21: =C21*53 -> 0 | F21: =E21*53 -> 0 | J21: =+D21+F21+H21+I21 -> 0 | M21: Kommentar: - Beschreibung = Lieferant oder Ware (z.B. "Werinox","Plattenmaterial", "Kammerrahmen", etc) - Kommentar = z.B. "angefragt", "bestellt", "geliefert" - Wert = Bestellwert MF - in PA = Nach PA-Beginn wird "Wert" nach rechts "in PA" verschoben und "Wert" auf null gesetzt. Dies kann anteilig nötig sein wenn bestelltes Material in verschiede PAs aufgeht.
D22: =C22*53 -> 0 | F22: =E22*53 -> 0 | J22: =+D22+F22+H22+I22 -> 0
D23: =C23*53 -> 0 | F23: =E23*53 -> 0 | J23: =+D23+F23+H23+I23 -> 0
B24: Gesamt | C24: =SUM(C14:C23) -> 5 | D24: =SUM(D14:D23) -> 250 | E24: =SUM(E14:E23) -> 20 | F24: =SUM(F14:F23) -> 1000 | G24: =SUM(G14:G23) -> 0 | H24: =SUM(H14:H23) -> 2096.5 | I24: =SUM(I14:I23) -> 10568.78 | J24: =SUM(J14:J23) -> 13915.28
B26: PM | C26: PMK | D26: Konstruktion | E26: KOK | F26: VK / Vertriebsunterstützung
B28: Stunden | C28: Kosten | D28: Stunden | E28: Kosten | F28: Stunden | G28: Kosten
B29: 0 | C29: =B29*53 -> 0 | D29: 32.75 | E29: =D29*53 -> 1735.75 | F29: 0 | G29: =F29*53 -> 0
B31: Einkauf
B32: Beschreibung | C32: BE-Nummer | D32: Kommentar | F32: Wert | G32: in PA
B48: Gesamt | F48: =SUM(F33:F47) -> 0 | G48: EKM
B50: Produktion | C50: laufende PAs | G50: Lohn-Plankosten | H50: abgeschlossene PAs | M50: PA Auswertung Status und Lohnkosten | Q50: Kommentar: - Reihenfolge der PA-Einträge muss Reihenfolge in MF entsprechen - Plankosten = Summe der Lohn-Plankosten MF - Arbeit = Summe der Lohn-Istkosten MF - offene Arbeit = Plankosten minus Lohn-Plankosten (MF) der abgeschlossenen Arbeitsschritte - Abgeschlossene PAs, die noch nciht aufgegangen sind, werden ausgegraut - Abgeschlossenen PAs, die aufgegangen sind, werden anch rechts verschoben und links entfernt
B51: Produktionsaufträge | C51: Arbeit | D51: Material | E51: Summe | F51: offen Arbeit | G51: Arbeit | H51: Arbeit | I51: Material | J51: Summe | K51: Status | L51: Artikel Nr. - Bezeichnung | M51: Erwartete Abarbeitung | N51: Verbrauchte Plankosten | O51: Kostenabweichung
B52: PA061254 | E52: =C52+D52 -> 0 | F52: 234.5238 | G52: 234.5238 | J52: =H52+I52 -> 0 | K52: Eingeplant | L52: TR-8880-19709 - kundenspezfische Hochvakuumkammer DN600 | M52: =IF(AND(G52>0,OR(C52>0,F52>0,H52>0)),(G52-F52)/G52,"") -> 0 | N52: =IF(G52>0,(IF(C52>0,C52,H52))/G52,"") -> 0 | O52: =IF(M52=100%,G52-(IF(C52>0,C52,H52)),"") | P52: 40866
B53: PA061255 | E53: =C53+D53 -> 0 | F53: 78.75 | G53: 78.75 | J53: =H53+I53 -> 0 | K53: Eingeplant | L53: TR-0000072423 - Tür DN600 bearbeitet | M53: =IF(AND(G53>0,OR(C53>0,F53>0,H53>0)),(G53-F53)/G53,"") -> 0 | N53: =IF(G53>0,(IF(C53>0,C53,H53))/G53,"") -> 0 | O53: =IF(M53=100%,G53-(IF(C53>0,C53,H53)),"") | P53: 40867
B54: PA061257 | D54: 424.8836 | E54: =C54+D54 -> 424.8836 | F54: 399.4153 | G54: 399.4153 | J54: =H54+I54 -> 0 | K54: Angearbeitet | L54: TR-0000072423-R - Tür DN600 bearbeitet - Roh | M54: =IF(AND(G54>0,OR(C54>0,F54>0,H54>0)),(G54-F54)/G54,"") -> 0 | N54: =IF(G54>0,(IF(C54>0,C54,H54))/G54,"") -> 0 | O54: =IF(M54=100%,G54-(IF(C54>0,C54,H54)),"") | P54: 40868
B55: PA061258 | E55: =C55+D55 -> 0 | F55: 270 | G55: 270 | J55: =H55+I55 -> 0 | K55: Eingeplant | L55: TR-0000072419 - Kammerkorpus, DN 600 | M55: =IF(AND(G55>0,OR(C55>0,F55>0,H55>0)),(G55-F55)/G55,"") -> 0 | N55: =IF(G55>0,(IF(C55>0,C55,H55))/G55,"") -> 0 | O55: =IF(M55=100%,G55-(IF(C55>0,C55,H55)),"") | P55: 40869
B56: PA061260 | C56: 203.8734 | D56: 2233.5035 | E56: =C56+D56 -> 2437.3769 | F56: 3662.9137 | G56: 3992.9137 | J56: =H56+I56 -> 0 | K56: Angearbeitet | L56: TR-0000072419-R - Kammerkorpus, DN 600 - Roh | M56: =IF(AND(G56>0,OR(C56>0,F56>0,H56>0)),(G56-F56)/G56,"") -> 0.082646414 | N56: =IF(G56>0,(IF(C56>0,C56,H56))/G56,"") -> 0.051058805 | O56: =IF(M56=100%,G56-(IF(C56>0,C56,H56)),"") | P56: 40870
B57: PA061261 | D57: 11.16 | E57: =C57+D57 -> 11.16 | F57: 18.4138 | G57: 18.4138 | J57: =H57+I57 -> 0 | K57: Angearbeitet | L57: TR-0000072422 - Typenschild beschriftet | M57: =IF(AND(G57>0,OR(C57>0,F57>0,H57>0)),(G57-F57)/G57,"") -> 0 | N57: =IF(G57>0,(IF(C57>0,C57,H57))/G57,"") -> 0 | O57: =IF(M57=100%,G57-(IF(C57>0,C57,H57)),"") | P57: 40871
B58: PA061262 | C58: 192.401 | D58: 51.1344 | E58: =C58+D58 -> 243.5354 | F58: 43 | G58: 412 | J58: =H58+I58 -> 0 | K58: Angearbeitet | L58: TR-0000073137 - Halter Auszug | M58: =IF(AND(G58>0,OR(C58>0,F58>0,H58>0)),(G58-F58)/G58,"") -> 0.89563107 | N58: =IF(G58>0,(IF(C58>0,C58,H58))/G58,"") -> 0.46699272 | O58: =IF(M58=100%,G58-(IF(C58>0,C58,H58)),"") | P58: 40872
B59: PA061263 | E59: =C59+D59 -> 0 | F59: 78.75 | G59: 78.75 | J59: =H59+I59 -> 0 | K59: Eingeplant | L59: TR-0000072611 - Tür DN600 bearbeitet | M59: =IF(AND(G59>0,OR(C59>0,F59>0,H59>0)),(G59-F59)/G59,"") -> 0 | N59: =IF(G59>0,(IF(C59>0,C59,H59))/G59,"") -> 0 | O59: =IF(M59=100%,G59-(IF(C59>0,C59,H59)),"") | P59: 40882
B60: PA061265 | D60: 251.895 | E60: =C60+D60 -> 251.895 | F60: 341.6653 | G60: 341.6653 | J60: =H60+I60 -> 0 | K60: Angearbeitet | L60: TR-0000072611-R - Tür DN600 bearbeitet - Roh | M60: =IF(AND(G60>0,OR(C60>0,F60>0,H60>0)),(G60-F60)/G60,"") -> 0 | N60: =IF(G60>0,(IF(C60>0,C60,H60))/G60,"") -> 0 | O60: =IF(M60=100%,G60-(IF(C60>0,C60,H60)),"") | P60: 41044
B61: PA061266 | E61: =C61+D61 -> 0 | F61: 0.498 | G61: 0.498 | J61: =H61+I61 -> 0 | K61: Eingeplant | L61: TR-0000074647 - BG Schiene | M61: =IF(AND(G61>0,OR(C61>0,F61>0,H61>0)),(G61-F61)/G61,"") -> 0 | N61: =IF(G61>0,(IF(C61>0,C61,H61))/G61,"") -> 0 | O61: =IF(M61=100%,G61-(IF(C61>0,C61,H61)),"")
B62: PA061267 | E62: =C62+D62 -> 0 | F62: 259.6653 | G62: 259.6653 | J62: =H62+I62 -> 0 | K62: Eingeplant | L62: TR-0000075541 - SFC / LFC - Klemmblöck bearbeitet | M62: =IF(AND(G62>0,OR(C62>0,F62>0,H62>0)),(G62-F62)/G62,"") -> 0 | N62: =IF(G62>0,(IF(C62>0,C62,H62))/G62,"") -> 0 | O62: =IF(M62=100%,G62-(IF(C62>0,C62,H62)),"")
B63: PA061268 | E63: =C63+D63 -> 0 | F63: 1.998 | G63: 1.998 | J63: =H63+I63 -> 0 | K63: Eingeplant | L63: 820KBH0500-020 - Scharnier | M63: =IF(AND(G63>0,OR(C63>0,F63>0,H63>0)),(G63-F63)/G63,"") -> 0 | N63: =IF(G63>0,(IF(C63>0,C63,H63))/G63,"") -> 0 | O63: =IF(M63=100%,G63-(IF(C63>0,C63,H63)),"")
...

Sheet KW53
M2: Kommentar: - Stundensatz Jan 2024 auf 50€ erhöht - Bitte in VK eintragen wie in VK gerechnet
B3: Auftraggeber | C3: Projektleiter | D3: Projektnummer | E3: Projektkategorie | F3: Umsatz | G3: Liefertermin AB | H3: Endtermin | I3: Marge geplant | J3: Gesamtstatus
B4: =+Info!B7 -> PFEIFFER BENELUX | C4: =+Info!B15 -> Plomer | D4: =+Info!B6 -> P47551 | E4: =+Info!B5 -> B | F4: =+Info!B9+Info!B11+Info!C11+Info!D11+Info!E11 -> 27274.5 | G4: =+Info!B13 -> 45915 | I4: =(F4-(J24*1.05))/F4 -> 0.46429654
B7: Artikelnummer(n) | C7: =+Info!B19 -> TR-8880-19709
B8: Artikelbeschreibung | C8: =+Info!B20 -> kundenspezfische Hochvakuumkammer DN600 Horizontal Länge: 900 mm
B9: Besonderheiten | C9: =+Info!B21 -> 0
B11: Vorkalkulation(en)
C12: PM (PMK) | E12: Konstruktion (KOK) | G12: Fertigung | I12: Material | J12: Gesamt
C13: Stunden | D13: Kosten | E13: Stunden | F13: Kosten | G13: Stunden | H13: Kosten | I13: Kosten
B14: VK2400337 | C14: 5 | D14: 250 | E14: 20 | F14: 1000 | H14: 2096.5 | I14: 10568.78 | J14: 13915.28
D15: =C15*53 -> 0 | F15: =E15*53 -> 0 | J15: =+D15+F15+H15+I15 -> 0
D16: =C16*53 -> 0 | F16: =E16*53 -> 0 | J16: =+D16+F16+H16+I16 -> 0
D17: =C17*53 -> 0 | F17: =E17*53 -> 0 | J17: =+D17+F17+H17+I17 -> 0 | M17: Kommentar: - Bisher in MF erfaßt Stunden
D18: =C18*53 -> 0 | F18: =E18*53 -> 0 | J18: =+D18+F18+H18+I18 -> 0
D19: =C19*53 -> 0 | F19: =E19*53 -> 0 | J19: =+D19+F19+H19+I19 -> 0
D20: =C20*53 -> 0 | F20: =E20*53 -> 0 | J20: =+D20+F20+H20+I20 -> 0
D21: =C21*53 -> 0 | F21: =E21*53 -> 0 | J21: =+D21+F21+H21+I21 -> 0 | M21: Kommentar: - Beschreibung = Lieferant oder Ware (z.B. "Werinox","Plattenmaterial", "Kammerrahmen", etc) - Kommentar = z.B. "angefragt", "bestellt", "geliefert" - Wert = Bestellwert MF - in PA = Nach PA-Beginn wird "Wert" nach rechts "in PA" verschoben und "Wert" auf null gesetzt. Dies kann anteilig nötig sein wenn bestelltes Material in verschiede PAs aufgeht.
D22: =C22*53 -> 0 | F22: =E22*53 -> 0 | J22: =+D22+F22+H22+I22 -> 0
D23: =C23*53 -> 0 | F23: =E23*53 -> 0 | J23: =+D23+F23+H23+I23 -> 0
B24: Gesamt | C24: =SUM(C14:C23) -> 5 | D24: =SUM(D14:D23) -> 250 | E24: =SUM(E14:E23) -> 20 | F24: =SUM(F14:F23) -> 1000 | G24: =SUM(G14:G23) -> 0 | H24: =SUM(H14:H23) -> 2096.5 | I24: =SUM(I14:I23) -> 10568.78 | J24: =SUM(J14:J23) -> 13915.28
B26: PM | C26: PMK | D26: Konstruktion | E26: KOK | F26: VK / Vertriebsunterstützung
B28: Stunden | C28: Kosten | D28: Stunden | E28: Kosten | F28: Stunden | G28: Kosten
B29: 0 | C29: =B29*53 -> 0 | D29: 32.75 | E29: =D29*53 -> 1735.75 | F29: 0 | G29: =F29*53 -> 0
B31: Einkauf
B32: Beschreibung | C32: BE-Nummer | D32: Kommentar | F32: Wert | G32: in PA
B48: Gesamt | F48: =SUM(F33:F47) -> 0 | G48: EKM
B50: Produktion | C50: laufende PAs | G50: Lohn-Plankosten | H50: abgeschlossene PAs | M50: PA Auswertung Status und Lohnkosten | Q50: Kommentar: - Reihenfolge der PA-Einträge muss Reihenfolge in MF entsprechen - Plankosten = Summe der Lohn-Plankosten MF - Arbeit = Summe der Lohn-Istkosten MF - offene Arbeit = Plankosten minus Lohn-Plankosten (MF) der abgeschlossenen Arbeitsschritte - Abgeschlossene PAs, die noch nciht aufgegangen sind, werden ausgegraut - Abgeschlossenen PAs, die aufgegangen sind, werden anch rechts verschoben und links entfernt
B51: Produktionsaufträge | C51: Arbeit | D51: Material | E51: Summe | F51: offen Arbeit | G51: Arbeit | H51: Arbeit | I51: Material | J51: Summe | K51: Status | L51: Artikel Nr. - Bezeichnung | M51: Erwartete Abarbeitung | N51: Verbrauchte Plankosten | O51: Kostenabweichung
B52: PA061254 | E52: =C52+D52 -> 0 | F52: 250.1398 | G52: 250.1398 | J52: =H52+I52 -> 0 | K52: Eingeplant | L52: TR-8880-19709 - kundenspezfische Hochvakuumkammer DN600 | M52: =IF(AND(G52>0,OR(C52>0,F52>0,H52>0)),(G52-F52)/G52,"") -> 0 | N52: =IF(G52>0,(IF(C52>0,C52,H52))/G52,"") -> 0 | O52: =IF(M52=100%,G52-(IF(C52>0,C52,H52)),"") | P52: 40866
B53: PA061255 | E53: =C53+D53 -> 0 | F53: 160.25 | G53: 160.25 | J53: =H53+I53 -> 0 | K53: Eingeplant | L53: TR-0000072423 - Tür DN600 bearbeitet | M53: =IF(AND(G53>0,OR(C53>0,F53>0,H53>0)),(G53-F53)/G53,"") -> 0 | N53: =IF(G53>0,(IF(C53>0,C53,H53))/G53,"") -> 0 | O53: =IF(M53=100%,G53-(IF(C53>0,C53,H53)),"") | P53: 40867
B54: PA061257 | C54: 751.3242 | D54: 424.8836 | E54: =C54+D54 -> 1176.2078 | F54: 340 | G54: 594.1651 | J54: =H54+I54 -> 0 | K54: Angearbeitet | L54: TR-0000072423-R - Tür DN600 bearbeitet - Roh | M54: =IF(AND(G54>0,OR(C54>0,F54>0,H54>0)),(G54-F54)/G54,"") -> 0.42776848 | N54: =IF(G54>0,(IF(C54>0,C54,H54))/G54,"") -> 1.2645041 | O54: =IF(M54=100%,G54-(IF(C54>0,C54,H54)),"") | P54: 40868
B55: PA061258 | E55: =C55+D55 -> 0 | F55: 458 | G55: 458 | J55: =H55+I55 -> 0 | K55: Eingeplant | L55: TR-0000072419 - Kammerkorpus, DN 600 | M55: =IF(AND(G55>0,OR(C55>0,F55>0,H55>0)),(G55-F55)/G55,"") -> 0 | N55: =IF(G55>0,(IF(C55>0,C55,H55))/G55,"") -> 0 | O55: =IF(M55=100%,G55-(IF(C55>0,C55,H55)),"") | P55: 40869
B56: PA061260 | E56: =C56+D56 -> 0 | G56: 5178.7456 | H56: 5631.7132 | I56: 2778.6057 | J56: =H56+I56 -> 8410.3189 | K56: Fertiggemeldet | L56: TR-0000072419-R - Kammerkorpus, DN 600 - Roh | M56: =IF(AND(G56>0,OR(C56>0,F56>0,H56>0)),(G56-F56)/G56,"") -> 1 | N56: =IF(G56>0,(IF(C56>0,C56,H56))/G56,"") -> 1.0874667 | O56: =IF(M56=100%,G56-(IF(C56>0,C56,H56)),"") -> -452.9676 | P56: 40870
B57: PA061261 | E57: =C57+D57 -> 0 | G57: 22.2466 | H57: 42.7508 | I57: 11.16 | J57: =H57+I57 -> 53.9108 | K57: Fertiggemeldet | L57: TR-0000072422 - Typenschild beschriftet | M57: =IF(AND(G57>0,OR(C57>0,F57>0,H57>0)),(G57-F57)/G57,"") -> 1 | N57: =IF(G57>0,(IF(C57>0,C57,H57))/G57,"") -> 1.9216779 | O57: =IF(M57=100%,G57-(IF(C57>0,C57,H57)),"") -> -20.5042 | P57: 40871
B58: PA061262 | E58: =C58+D58 -> 0 | G58: 433.5 | H58: 440.0198 | I58: 51.1344 | J58: =H58+I58 -> 491.1542 | K58: Fertiggemeldet | L58: TR-0000073137 - Halter Auszug | M58: =IF(AND(G58>0,OR(C58>0,F58>0,H58>0)),(G58-F58)/G58,"") -> 1 | N58: =IF(G58>0,(IF(C58>0,C58,H58))/G58,"") -> 1.0150399 | O58: =IF(M58=100%,G58-(IF(C58>0,C58,H58)),"") -> -6.5198 | P58: 40872
B59: PA061263 | E59: =C59+D59 -> 0 | F59: 160.25 | G59: 160.25 | J59: =H59+I59 -> 0 | K59: Eingeplant | L59: TR-0000072611 - Tür DN600 bearbeitet | M59: =IF(AND(G59>0,OR(C59>0,F59>0,H59>0)),(G59-F59)/G59,"") -> 0 | N59: =IF(G59>0,(IF(C59>0,C59,H59))/G59,"") -> 0 | O59: =IF(M59=100%,G59-(IF(C59>0,C59,H59)),"") | P59: 40882
B60: PA061265 | E60: =C60+D60 -> 0 | G60: 523.6651 | H60: 1041.4652 | I60: 251.895 | J60: =H60+I60 -> 1293.3602 | K60: Fertiggemeldet | L60: TR-0000072611-R - Tür DN600 bearbeitet - Roh | M60: =IF(AND(G60>0,OR(C60>0,F60>0,H60>0)),(G60-F60)/G60,"") -> 1 | N60: =IF(G60>0,(IF(C60>0,C60,H60))/G60,"") -> 1.9888001 | O60: =IF(M60=100%,G60-(IF(C60>0,C60,H60)),"") -> -517.8001 | P60: 41044
B61: PA061266 | E61: =C61+D61 -> 0 | F61: 0.6142 | G61: 0.6142 | J61: =H61+I61 -> 0 | K61: Eingeplant | L61: TR-0000074647 - BG Schiene | M61: =IF(AND(G61>0,OR(C61>0,F61>0,H61>0)),(G61-F61)/G61,"") -> 0 | N61: =IF(G61>0,(IF(C61>0,C61,H61))/G61,"") -> 0 | O61: =IF(M61=100%,G61-(IF(C61>0,C61,H61)),"")
B62: PA061267 | D62: 158.16 | E62: =C62+D62 -> 158.16 | F62: 271.6651 | G62: 271.6651 | J62: =H62+I62 -> 0 | K62: Angearbeitet | L62: TR-0000075541 - SFC / LFC - Klemmblöck bearbeitet | M62: =IF(AND(G62>0,OR(C62>0,F62>0,H62>0)),(G62-F62)/G62,"") -> 0 | N62: =IF(G62>0,(IF(C62>0,C62,H62))/G62,"") -> 0 | O62: =IF(M62=100%,G62-(IF(C62>0,C62,H62)),"")
B63: PA061268 | E63: =C63+D63 -> 0 | G63: 2.4642 | H63: 0 | I63: 1390.4696 | J63: =H63+I63 -> 1390.4696 | K63: Fertiggemeldet | L63: 820KBH0500-020 - Scharnier | M63: =IF(AND(G63>0,OR(C63>0,F63>0,H63>0)),(G63-F63)/G63,"") | N63: =IF(G63>0,(IF(C63>0,C63,H63))/G63,"") -> 0 | O63: =IF(M63=100%,G63-(IF(C63>0,C63,H63)),"")
...
